Workbook
Name _________________________________mf5: #REF!
Name _________________________________mf5: #REF!
Name _________________________________mf5: #REF!
Name _________________________________mf6: #REF!
Name _________________________________mf6: #REF!
Name _________________________________mf6: #REF!
Name _________________________________pc200: #REF!
Name _______________________________mf5: #REF!
Name _______________________________mf5: #REF!
Name _______________________________mf5: #REF!
Name _______________________________mf6: #REF!
Name _______________________________mf6: #REF!
Name _______________________________mf6: #REF!
Name _______________________________pc200: #REF!
Name ______________________________mf5: #REF!
Name ______________________________mf5: #REF!
Name ______________________________mf5: #REF!
Name ______________________________mf6: #REF!
Name ______________________________mf6: #REF!
Name ______________________________mf6: #REF!
Name ______________________________pc200: #REF!
Name _____________________________mf5: #REF!
Name _____________________________mf5: #REF!
Name _____________________________mf5: #REF!
Name _____________________________mf6: #REF!
Name _____________________________mf6: #REF!
Name _____________________________mf6: #REF!
Name _____________________________pc200: #REF!
Name ____________________________mf5: #REF!
Name ____________________________mf5: #REF!
Name ____________________________mf5: #REF!
Name ____________________________mf6: #REF!
Name ____________________________mf6: #REF!
Name ____________________________mf6: #REF!
Name ____________________________pc200: #REF!
Name ___________________________mf5: #REF!
Name ___________________________mf5: #REF!
Name ___________________________mf5: #REF!
Name ___________________________mf6: #REF!
Name ___________________________mf6: #REF!
Name ___________________________mf6: #REF!
Name ___________________________pc200: #REF!
Name __________________________mf5: #REF!
Name __________________________mf5: #REF!
Name __________________________mf5: #REF!
Name __________________________mf6: #REF!
Name __________________________mf6: #REF!
Name __________________________mf6: #REF!
Name __________________________pc200: #REF!
Name _________________________mf5: #REF!
Name _________________________mf5: #REF!
Name _________________________mf5: #REF!
Name _________________________mf6: #REF!
Name _________________________mf6: #REF!
Name _________________________mf6: #REF!
Name _________________________pc200: #REF!
Name ________________________mf5: #REF!
Name ________________________mf5: #REF!
Name ________________________mf5: #REF!
Name ________________________mf6: #REF!

Sheet Daftar
B1: Daftar Plasma/Mitra PT.Dwi Mitra Adhiusaha
B2: No. | C2: Mitra/Plasma | D2: Alamat | E2: NPWP | F2: NIK | G2: Cek NIK | H2: % | I2: Luas (M2)
B3: 1 | C3: Koperasi Produsen Pelangi Tanggul Harapan | D3: Tanggul Harapan No.9 Rt.002 Rw.001, Pematang Limau, Kab.Seruyan | E3: 63.797.965.9-712.000 | F3: -
B4: =B3+1 -> 2 | C4: Koperasi Produsen Berkah Natai Mandiri | D4: Jl.Desa Natai Baru Rt.001 Rw.001, Natai Baru, Kab.Kotawaringin Timur | E4: 63.087.816.3-712.000 | F4: -
B5: =B4+1 -> 3 | C5: Koperasi Pracara Mitra Bersama | D5: Jl.Jenderal Sudirman KM.45, Natai Baru, Kab.Kotawaringin Timur | E5: 81.722.395.1-712.000 | F5: -
B6: =B5+1 -> 4 | C6: Achram Syah Jenie | D6: Puri Bintaro P8.37/5 RTt.008 Rw.009 Sawah Baru, Ciputat, Tangerang Selatan, Banten | E6: - | F6: 3674041704650003 | G6: ü | I6: 174957
B7: =B6+1 -> 5 | C7: Dharma Irawan Jenie | D7: Jl. Hang Lekir VII/16. Rt.008 Rw.006, Gunung, Kebayoran Baru, Jakarta Selatan, DKI Jakarta | E7: - | F7: 3174071406570001 | G7: ü | I7: 139546
B8: =B7+1 -> 6 | C8: Dra. Gadis Naindra | D8: BSD Blok i3/30 Sektor 1-7. RT.001 Rw.011, Lengkong Gudang Timur, Serpong, Tangerang Selatan, Banten | E8: - | F8: 3674015709630001 | G8: ü | I8: 150375
B9: =B8+1 -> 7 | C9: R. Hestu Mawarsid, IR, MBA | D9: Jl. Kutisari 5/23 RT 001 RW 001. Kutisari,Tenggus Mejoyo | E9: 17.135.818.7-615.000 | F9: 3578241410590002 | G9: ü | I9: 153000
B10: =B9+1 -> 8 | C10: Widjojo Adi Hardono | D10: Jl. Pinang Merah IV / 24, Pondok Pinang, Kebayoran Lama, Jakarta Selatan | E10: 59.635.756.6-013.000 | F10: 3174050306700008 | G10: ü | I10: 356810
B11: =B10+1 -> 9 | C11: Aditya Wardhana | D11: Jl. Raya Taman Cimanggu No.36,Kedungwaringin,Tanah Sareal, Kota Bogor | E11: 09.222.759.4-404.000 | F11: 3271060101640004 | G11: ü | I11: 253106
B12: =B11+1 -> 10 | C12: Ir. Ariyanto Rahardjo, B.S | D12: Jl. Raya Taman Cimanggu No.36,Kedungwaringin,Tanah Sareal, Kota Bogor | E12: 09.224.817.8-404.000 | F12: 3271062310610005 | G12: ü | I12: 252804
B13: =B12+1 -> 11 | C13: Nadia Putri Asrini Jenie | D13: Jl. Kebon Nanas PWI No.36,Cipinang Besar Selatan,Jatinegara, Jakarta Timur | E13: 07.290.863.5-002.000 | F13: 3175035109810007 | G13: ü | I13: 100000
B14: =B13+1 -> 12 | C14: Endra Sukmana Haris, SE | D14: Jl. Kebon Nanas PWI No.36,Cipinang Besar Selatan,Jatinegara, Jakarta Timur | E14: 24.241.437.3-008.000 | F14: 3175031704780013 | G14: ü | I14: 30000
B15: =B14+1 -> 13 | C15: Fajria Putri Adriani | D15: Jl. Kebon Nanas PWI No.36,Cipinang Besar Selatan,Jatinegara, Jakarta Timur | E15: 59.057.015.6-002.000 | F15: 3175035212850011 | G15: ü | I15: 130000
B16: =B15+1 -> 14 | C16: M.Ikhsan Adriansyah Jenie | D16: Jl. Kebon Nanas PWI No.36,Cipinang Besar Selatan,Jatinegara, Jakarta Timur | E16: 59.057.014.9-002.000 | F16: 3175032201870006 | G16: ü | I16: 260000
B17: =B16+1 -> 15 | C17: Rini Azwien Jenie | D17: Jl. Kebon Nanas PWI No.36,Cipinang Besar Selatan,Jatinegara, Jakarta Timur | E17: 04.064.930.3-002.001 | F17: 3175034707560008 | G17: ü | I17: 520000
... B23: =B22+1 -> 21 | C23: DR Tjepy F Aloewie, MSC, SPOK | D23: Komp. Depnakertrans No.37, Jakasampurna, Bekasi Barat, Kota Bekasi | E23: 05.339.070.4-407.000 | F23: 3275020505490012 | G23: ü | I23: 239000
B24: =B23+1 -> 22 | C24: Nalia Indriani | D24: Jl. Bambu Duri 7 No.4 Rt.013 Rw.006, Pondok Bambu, Duren Sawit, Jakarta Timur, DKI Jakarta | E24: - | F24: 3175074709790012 | I24: 40000
B25: =B24+1 -> 23 | C25: Elise Fauzia Jenie | D25: Jl.DR.Muwardi III.24 Rt.002 Rw.003 Grogol, Grogol Petamburan, Jakarta Barat, DKI Jakarta | E25: - | F25: 3173025507690008 | G25: ü | I25: 40000
B26: =B25+1 -> 24 | C26: Dimas Mahardhika Jenie | D26: Jl. Pelikan III Blok U-6/17 RT.006 Rw.007, Rengas, Ciputat Timur, Tangerang Selatan, Banten | E26: - | F26: 3674051204820001 | G26: ü | I26: 40000
B27: =B26+1 -> 25 | C27: Aditya Fajar Meidiansyah | D27: Jl. Dr Semeru No.102 Rt.001 Rw.001, Menteng, Kota Bogor Barat, Kota Bogor, Jawa Barat | E27: - | F27: 3271040505900035 | G27: ü | I27: 60000
B28: =B27+1 -> 26 | C28: Siti Rizanie | D28: Bukit Golf Riverside I Blok A5/31, Bojong Nangka, Gunung Putri, Bogor, Jawa Barat | E28: - | F28: 3201026210740008 | G28: ü | I28: 40000
B29: =B28+1 -> 27 | C29: Rizka Amalia Aminudin | D29: Jl. Dewi-Dewi No.245 Rt.006 Rw.001, Rawa Badak Utara, Koja, Jakarta Utara, DKI Jakarta | E29: - | F29: 3674054707920001 | G29: ü | I29: 40000
B30: =B29+1 -> 28 | C30: Reza Pahlevi Satrio Jenie | D30: Jl. Parkit I Blok Y-I No.4 Rt.001 Rw.005, Rengas, Ciputat Timur, Tangerang Selatan, Banten | E30: - | F30: 3674050509770001 | G30: ü | I30: 60000
B31: =B30+1 -> 29 | C31: Mira Nuria | D31: Jl. Bambu Duri 7 No.4 Rt.013 Rw.006, Pondok Bambu, Duren Sawit, Jakarta Timur, DKI Jakarta | E31: - | F31: 3174066409770008 | G31: ü | I31: 40000
B32: =B31+1 -> 30 | C32: Daniel Roushdy Jenie | D32: Jl. Sutera Onyx VIII No 7 Alam Sutera, Pakualam, Serpong Utara, Tangerang Selatan, Banten | E32: - | F32: 3674021312700001 | G32: ü | I32: 40000
B33: =B32+1 -> 31 | C33: Iqra Gantira | D33: Gading Raya H 267 Rt.010 Rw.011, Pondok Bambu, Duren Sawit, Jakarta Timur, DKI Jakarta | E33: - | F33: 3175070305820001 | G33: ü | I33: 60000
B34: =B33+1 -> 32
B35: =B34+1 -> 33
B37: Note :
B38: 1. | C38: Pengecekan NIK Menggunakan Sistem BPJS Kesehatan, Jika tidak ada di sistem pajak mungkin berbeda penulisan nama (Spasi, Gelar, dll)
B39: 2. | C39: NIK yang belum ada di sistem BPJS dicetak merah, mungkin dapat dicek ke Sistem Pajak dahulu sebelum minta NPWP

Sheet Plasma I 01
A8: TAGIHAN BIAYA KEBUN PLASMA I PERIODE JANUARI 2025 | J8: REKAP
A11: N0 | B11: Lahan | C11: PEMINJAMAN | G11: HARGA | I11: No | J11: NAMA | K11: Lahan | L11: JUMLAH | M11: SAT | N11: HARGA | O11: TOTAL
C12: PEMBEBANAN | D12: NAMA BAHAN | E12: JUMLAH | F12: SAT | G12: HARGA SAT | H12: JUMLAH
I13: Pemakaian Bahan
A14: 1 | B14: Plasma I | C14: Bahan Plasma I | D14: Supremo | E14: 5.09712 | F14: Ltr | G14: 31860.083 | H14: =+E14*G14 -> 162394.67 | I14: =A14 -> 1 | J14: =D14 -> Supremo | K14: =+B14 -> Plasma I | L14: =SUMIFS($E$14:$E$166,$D$14:$D$166,J14,$B$14:$B$166,K14) -> 5.09712 | M14: =+F14 -> Ltr | N14: =O14/L14 -> 31860.083 | O14: =SUMIFS($H$14:$H$166,$D$14:$D$166,J14,$B$14:$B$166,K14) -> 162394.67 | P14: =H14-O14 -> 0 | Q14: Material
A15: =A14+1 -> 2 | B15: Plasma I | C15: Bahan Plasma I | D15: Trendy | E15: 318.57 | F15: Gr | G15: 85.565418 | H15: =+E15*G15 -> 27258.575 | I15: =A15 -> 2 | J15: =D15 -> Trendy | K15: =+B15 -> Plasma I | L15: =SUMIFS($E$14:$E$166,$D$14:$D$166,J15,$B$14:$B$166,K15) -> 318.57 | M15: =+F15 -> Gr | N15: =O15/L15 -> 85.565418 | O15: =SUMIFS($H$14:$H$166,$D$14:$D$166,J15,$B$14:$B$166,K15) -> 27258.575 | P15: =H15-O15 -> 0 | Q15: Material
A16: =A15+1 -> 3 | B16: Plasma I | C16: Bahan Plasma I | D16: Weed Solution | E16: 3.39808 | F16: Ltr | G16: 34019.211 | H16: =+E16*G16 -> 115600 | I16: =A16 -> 3 | J16: =D16 -> Weed Solution | K16: =+B16 -> Plasma I | L16: =SUMIFS($E$14:$E$166,$D$14:$D$166,J16,$B$14:$B$166,K16) -> 3.39808 | M16: =+F16 -> Ltr | N16: =O16/L16 -> 34019.211 | O16: =SUMIFS($H$14:$H$166,$D$14:$D$166,J16,$B$14:$B$166,K16) -> 115600 | P16: =H16-O16 -> 0 | Q16: Material
A17: =A16+1 -> 4 | B17: Plasma I | C17: Bahan Plasma I | D17: Supretox | E17: 7.055 | F17: Ltr | G17: 28708.437 | H17: =+E17*G17 -> 202538.02 | I17: =A17 -> 4 | J17: =D17 -> Supretox | K17: =+B17 -> Plasma I | L17: =SUMIFS($E$14:$E$166,$D$14:$D$166,J17,$B$14:$B$166,K17) -> 7.055 | M17: =+F17 -> Ltr | N17: =O17/L17 -> 28708.437 | O17: =SUMIFS($H$14:$H$166,$D$14:$D$166,J17,$B$14:$B$166,K17) -> 202538.02 | P17: =H17-O17 -> 0 | Q17: Material
A18: =A17+1 -> 5 | B18: Plasma I | C18: Bahan Plasma I | D18: Triester | E18: 2257.6 | F18: Cc | G18: 124.13864 | H18: =+E18*G18 -> 280255.39 | I18: =A18 -> 5 | J18: =D18 -> Triester | K18: =+B18 -> Plasma I | L18: =SUMIFS($E$14:$E$166,$D$14:$D$166,J18,$B$14:$B$166,K18) -> 2257.6 | M18: =+F18 -> Cc | N18: =O18/L18 -> 124.13864 | O18: =SUMIFS($H$14:$H$166,$D$14:$D$166,J18,$B$14:$B$166,K18) -> 280255.39 | P18: =H18-O18 -> 0 | Q18: Material
A19: =A18+1 -> 6 | B19: Plasma I | C19: Bahan Plasma I | D19: Batu Bigros | E19: 1 | F19: Rit | G19: 2000000 | H19: =+E19*G19 -> 2000000 | I19: =A19 -> 6 | J19: =D19 -> Batu Bigros | K19: =+B19 -> Plasma I | L19: =SUMIFS($E$14:$E$166,$D$14:$D$166,J19,$B$14:$B$166,K19) -> 1 | M19: =+F19 -> Rit | N19: =O19/L19 -> 2000000 | O19: =SUMIFS($H$14:$H$166,$D$14:$D$166,J19,$B$14:$B$166,K19) -> 2000000 | P19: =H19-O19 -> 0 | Q19: Material
A20: =A19+1 -> 7 | B20: Plasma I | C20: Bahan Plasma I | D20: POMPA TRANSFER BBM FLOWMETER DIGITAL SOLAR AC 220V | E20: 0.0521 | F20: UNIT | G20: 6960000 | H20: =+E20*G20 -> 362616 | I20: =A20 -> 7 | J20: =D20 -> POMPA TRANSFER BBM FLOWMETER DIGITAL SOLAR AC 220V | K20: =+B20 -> Plasma I | L20: =SUMIFS($E$14:$E$166,$D$14:$D$166,J20,$B$14:$B$166,K20) -> 0.0521 | M20: =+F20 -> UNIT | N20: =O20/L20 -> 6960000 | O20: =SUMIFS($H$14:$H$166,$D$14:$D$166,J20,$B$14:$B$166,K20) -> 362616 | P20: =H20-O20 -> 0 | Q20: Material | XFD20: =SUM(A20:XFC20) -> 14645246
A21: =A20+1 -> 8 | B21: Plasma I | C21: Bahan Plasma I | D21: KIPAS ANGIN BERDIRI | E21: 0.1563 | F21: UNIT | G21: 350000 | H21: =+E21*G21 -> 54705 | I21: =A21 -> 8 | J21: =D21 -> KIPAS ANGIN BERDIRI | K21: =+B21 -> Plasma I | L21: =SUMIFS($E$14:$E$166,$D$14:$D$166,J21,$B$14:$B$166,K21) -> 0.1563 | M21: =+F21 -> UNIT | N21: =O21/L21 -> 350000 | O21: =SUMIFS($H$14:$H$166,$D$14:$D$166,J21,$B$14:$B$166,K21) -> 54705 | P21: =H21-O21 -> 0 | Q21: Material
A22: =A21+1 -> 9 | B22: Plasma I | C22: Bahan Plasma I | D22: TV LED 24" SHARF | E22: 0.0521 | F22: UNIT | G22: 1650000 | H22: =+E22*G22 -> 85965 | I22: =A22 -> 9 | J22: =D22 -> TV LED 24" SHARF | K22: =+B22 -> Plasma I | L22: =SUMIFS($E$14:$E$166,$D$14:$D$166,J22,$B$14:$B$166,K22) -> 0.0521 | M22: =+F22 -> UNIT | N22: =O22/L22 -> 1650000 | O22: =SUMIFS($H$14:$H$166,$D$14:$D$166,J22,$B$14:$B$166,K22) -> 85965 | P22: =H22-O22 -> 0 | Q22: Material
A23: =A22+1 -> 10 | B23: Plasma I | C23: Bahan Plasma I | D23: K. VISION SET PAYUNG | E23: 0.0521 | F23: UNIT | G23: 850000 | H23: =+E23*G23 -> 44285 | I23: =A23 -> 10 | J23: =D23 -> K. VISION SET PAYUNG | K23: =+B23 -> Plasma I | L23: =SUMIFS($E$14:$E$166,$D$14:$D$166,J23,$B$14:$B$166,K23) -> 0.0521 | M23: =+F23 -> UNIT | N23: =O23/L23 -> 850000 | O23: =SUMIFS($H$14:$H$166,$D$14:$D$166,J23,$B$14:$B$166,K23) -> 44285 | P23: =H23-O23 -> 0 | Q23: Material
A24: =A23+1 -> 11 | B24: Plasma I | C24: Bahan Plasma I | D24: CHECKING KRANI PANEN | E24: 0.1042 | F24: RIM | G24: 160000 | H24: =+E24*G24 -> 16672 | I24: =A24 -> 11 | J24: =D24 -> CHECKING KRANI PANEN | K24: =+B24 -> Plasma I | L24: =SUMIFS($E$14:$E$166,$D$14:$D$166,J24,$B$14:$B$166,K24) -> 0.1042 | M24: =+F24 -> RIM | N24: =O24/L24 -> 160000 | O24: =SUMIFS($H$14:$H$166,$D$14:$D$166,J24,$B$14:$B$166,K24) -> 16672 | P24: =H24-O24 -> 0 | Q24: Material
A25: =A24+1 -> 12 | B25: Plasma I | C25: Bahan Plasma I | D25: PENGANTAR TBS | E25: 0.1563 | F25: RIM | G25: 160000 | H25: =+E25*G25 -> 25008 | I25: =A25 -> 12 | J25: =D25 -> PENGANTAR TBS | K25: =+B25 -> Plasma I | L25: =SUMIFS($E$14:$E$166,$D$14:$D$166,J25,$B$14:$B$166,K25) -> 0.1563 | M25: =+F25 -> RIM | N25: =O25/L25 -> 160000 | O25: =SUMIFS($H$14:$H$166,$D$14:$D$166,J25,$B$14:$B$166,K25) -> 25008 | P25: =H25-O25 -> 0 | Q25: Material
A26: =A25+1 -> 13 | B26: Plasma I | C26: Bahan Plasma I | D26: DATA KWALITAS TBS | E26: 0.2605 | F26: RIM | G26: 160000 | H26: =+E26*G26 -> 41680 | I26: =A26 -> 13 | J26: =D26 -> DATA KWALITAS TBS | K26: =+B26 -> Plasma I | L26: =SUMIFS($E$14:$E$166,$D$14:$D$166,J26,$B$14:$B$166,K26) -> 0.2605 | M26: =+F26 -> RIM | N26: =O26/L26 -> 160000 | O26: =SUMIFS($H$14:$H$166,$D$14:$D$166,J26,$B$14:$B$166,K26) -> 41680 | P26: =H26-O26 -> 0 | Q26: Material
A27: =A26+1 -> 14 | B27: Plasma I | C27: Bahan Plasma I | D27: PERAWATAN | E27: 0.2605 | F27: RIM | G27: 160000 | H27: =+E27*G27 -> 41680 | I27: =A27 -> 14 | J27: =D27 -> PERAWATAN | K27: =+B27 -> Plasma I | L27: =SUMIFS($E$14:$E$166,$D$14:$D$166,J27,$B$14:$B$166,K27) -> 0.2605 | M27: =+F27 -> RIM | N27: =O27/L27 -> 160000 | O27: =SUMIFS($H$14:$H$166,$D$14:$D$166,J27,$B$14:$B$166,K27) -> 41680 | P27: =H27-O27 -> 0 | Q27: Material
A28: =A27+1 -> 15 | B28: Plasma I | C28: Bahan Plasma I | D28: ANCAK PANEN | E28: 0.521 | F28: RIM | G28: 160000 | H28: =+E28*G28 -> 83360 | I28: =A28 -> 15 | J28: =D28 -> ANCAK PANEN | K28: =+B28 -> Plasma I | L28: =SUMIFS($E$14:$E$166,$D$14:$D$166,J28,$B$14:$B$166,K28) -> 0.521 | M28: =+F28 -> RIM | N28: =O28/L28 -> 160000 | O28: =SUMIFS($H$14:$H$166,$D$14:$D$166,J28,$B$14:$B$166,K28) -> 83360 | P28: =H28-O28 -> 0 | Q28: Material
A29: =A28+1 -> 16 | B29: Plasma I | C29: Bahan Plasma I | D29: PENGEMBALIAN BARANG BEKAS | E29: 0.0521 | F29: RIM | G29: 160000 | H29: =+E29*G29 -> 8336 | I29: =A29 -> 16 | J29: =D29 -> PENGEMBALIAN BARANG BEKAS | K29: =+B29 -> Plasma I | L29: =SUMIFS($E$14:$E$166,$D$14:$D$166,J29,$B$14:$B$166,K29) -> 0.0521 | M29: =+F29 -> RIM | N29: =O29/L29 -> 160000 | O29: =SUMIFS($H$14:$H$166,$D$14:$D$166,J29,$B$14:$B$166,K29) -> 8336 | P29: =H29-O29 -> 0 | Q29: Material
A30: =A29+1 -> 17 | B30: Plasma I | C30: Bahan Plasma I | D30: SPB | E30: 0.0521 | F30: RIM | G30: 160000 | H30: =+E30*G30 -> 8336 | I30: =A30 -> 17 | J30: =D30 -> SPB | K30: =+B30 -> Plasma I | L30: =SUMIFS($E$14:$E$166,$D$14:$D$166,J30,$B$14:$B$166,K30) -> 0.0521 | M30: =+F30 -> RIM | N30: =O30/L30 -> 160000 | O30: =SUMIFS($H$14:$H$166,$D$14:$D$166,J30,$B$14:$B$166,K30) -> 8336 | P30: =H30-O30 -> 0 | Q30: Material
A31: =A30+1 -> 18 | B31: Plasma I | C31: Bahan Plasma I | D31: PASS KELUAR | E31: 0.0521 | F31: RIM | G31: 160000 | H31: =+E31*G31 -> 8336 | I31: =A31 -> 18 | J31: =D31 -> PASS KELUAR | K31: =+B31 -> Plasma I | L31: =SUMIFS($E$14:$E$166,$D$14:$D$166,J31,$B$14:$B$166,K31) -> 0.0521 | M31: =+F31 -> RIM | N31: =O31/L31 -> 160000 | O31: =SUMIFS($H$14:$H$166,$D$14:$D$166,J31,$B$14:$B$166,K31) -> 8336 | P31: =H31-O31 -> 0 | Q31: Material
A32: =A31+1 -> 19 | B32: Plasma I | C32: Bahan Plasma I | D32: LAP. PROGRAM LERJA DIVISI | E32: 0.0521 | F32: RIM | G32: 160000 | H32: =+E32*G32 -> 8336 | I32: =A32 -> 19 | J32: =D32 -> LAP. PROGRAM LERJA DIVISI | K32: =+B32 -> Plasma I | L32: =SUMIFS($E$14:$E$166,$D$14:$D$166,J32,$B$14:$B$166,K32) -> 0.0521 | M32: =+F32 -> RIM | N32: =O32/L32 -> 160000 | O32: =SUMIFS($H$14:$H$166,$D$14:$D$166,J32,$B$14:$B$166,K32) -> 8336 | P32: =H32-O32 -> 0 | Q32: Material
... A51: =A50+1 -> 38 | B51: Plasma I | C51: Bahan Plasma I | D51: GUNTING | E51: 0.0521 | F51: PCS | G51: 17000 | H51: =+E51*G51 -> 885.7 | I51: =A51 -> 38 | J51: =D51 -> GUNTING | K51: =+B51 -> Plasma I | L51: =SUMIFS($E$14:$E$166,$D$14:$D$166,J51,$B$14:$B$166,K51) -> 0.0521 | M51: =+F51 -> PCS | N51: =O51/L51 -> 17000 | O51: =SUMIFS($H$14:$H$166,$D$14:$D$166,J51,$B$14:$B$166,K51) -> 885.7 | P51: =H51-O51 -> 0 | Q51: Material
A52: =A51+1 -> 39 | B52: Plasma I | C52: Bahan Plasma I | D52: PEN KENKO | E52: 0.2605 | F52: PCS | G52: 5000 | H52: =+E52*G52 -> 1302.5 | I52: =A52 -> 39 | J52: =D53 -> POST IT | K52: =+B52 -> Plasma I | L52: =SUMIFS($E$14:$E$166,$D$14:$D$166,J52,$B$14:$B$166,K52) -> 0.1042 | M52: =F53 -> PCS | N52: =O52/L52 -> 24000 | O52: =SUMIFS($H$14:$H$166,$D$14:$D$166,J52,$B$14:$B$166,K52) -> 2500.8 | P52: =H52-O52 -> -1198.3 | Q52: Material
A53: =A52+1 -> 40 | B53: Plasma I | C53: Bahan Plasma I | D53: POST IT | E53: 0.1042 | F53: PCS | G53: 24000 | H53: =+E53*G53 -> 2500.8 | I53: =A53 -> 40 | J53: =D54 -> STELLA MATIC REFILL | K53: =+B53 -> Plasma I | L53: =SUMIFS($E$14:$E$166,$D$14:$D$166,J53,$B$14:$B$166,K53) -> 0.1563 | M53: =F54 -> PCS | N53: =O53/L53 -> 37000 | O53: =SUMIFS($H$14:$H$166,$D$14:$D$166,J53,$B$14:$B$166,K53) -> 5783.1 | P53: =H53-O53 -> -3282.3 | Q53: Material
A54: =A53+1 -> 41 | B54: Plasma I | C54: Bahan Plasma I | D54: STELLA MATIC REFILL | E54: 0.1563 | F54: PCS | G54: 37000 | H54: =+E54*G54 -> 5783.1 | I54: =A54 -> 41 | J54: =D55 -> TISSU 900GR | K54: =+B54 -> Plasma I | L54: =SUMIFS($E$14:$E$166,$D$14:$D$166,J54,$B$14:$B$166,K54) -> 0.0521 | M54: =F55 -> PCS | N54: =O54/L54 -> 50000 | O54: =SUMIFS($H$14:$H$166,$D$14:$D$166,J54,$B$14:$B$166,K54) -> 2605 | P54: =H54-O54 -> 3178.1 | Q54: Material
A55: =A54+1 -> 42 | B55: Plasma I | C55: Bahan Plasma I | D55: TISSU 900GR | E55: 0.0521 | F55: PCS | G55: 50000 | H55: =+E55*G55 -> 2605 | I55: =A55 -> 42 | J55: =D56 -> SOKLIN LANTAI | K55: =+B55 -> Plasma I | L55: =SUMIFS($E$14:$E$166,$D$14:$D$166,J55,$B$14:$B$166,K55) -> 0.4168 | M55: =F56 -> PCS | N55: =O55/L55 -> 16000 | O55: =SUMIFS($H$14:$H$166,$D$14:$D$166,J55,$B$14:$B$166,K55) -> 6668.8 | P55: =H55-O55 -> -4063.8 | Q55: Material
A56: =A55+1 -> 43 | B56: Plasma I | C56: Bahan Plasma I | D56: SOKLIN LANTAI | E56: 0.1563 | F56: PCS | G56: 16000 | H56: =+E56*G56 -> 2500.8 | I56: =A56 -> 43 | J56: =D57 -> MESIN POMPA AIR PANASONIC GP 200 JXK NON OTOMATIS | K56: =+B56 -> Plasma I | L56: =SUMIFS($E$14:$E$166,$D$14:$D$166,J56,$B$14:$B$166,K56) -> 0.0521 | M56: =F57 -> UNIT | N56: =O56/L56 -> 854800 | O56: =SUMIFS($H$14:$H$166,$D$14:$D$166,J56,$B$14:$B$166,K56) -> 44535.08 | P56: =H56-O56 -> -42034.28 | Q56: Material
A57: =A56+1 -> 44 | B57: Plasma I | C57: Bahan Plasma I | D57: MESIN POMPA AIR PANASONIC GP 200 JXK NON OTOMATIS | E57: 0.0521 | F57: UNIT | G57: 854800 | H57: =+E57*G57 -> 44535.08 | I57: =A57 -> 44 | J57: =D58 -> RAPIKA | K57: =+B57 -> Plasma I | L57: =SUMIFS($E$14:$E$166,$D$14:$D$166,J57,$B$14:$B$166,K57) -> 0.1042 | M57: =F58 -> BTL | N57: =O57/L57 -> 11000 | O57: =SUMIFS($H$14:$H$166,$D$14:$D$166,J57,$B$14:$B$166,K57) -> 1146.2 | P57: =H57-O57 -> 43388.88 | Q57: Material
A58: =A57+1 -> 45 | B58: Plasma I | C58: Bahan Plasma I | D58: RAPIKA | E58: 0.1042 | F58: BTL | G58: 11000 | H58: =+E58*G58 -> 1146.2 | I58: =A58 -> 45 | J58: =D59 -> SIKAT GIGI | K58: =+B58 -> Plasma I | L58: =SUMIFS($E$14:$E$166,$D$14:$D$166,J58,$B$14:$B$166,K58) -> 0.6252 | M58: =F59 -> BH | N58: =O58/L58 -> 12000 | O58: =SUMIFS($H$14:$H$166,$D$14:$D$166,J58,$B$14:$B$166,K58) -> 7502.4 | P58: =H58-O58 -> -6356.2 | Q58: Material
A59: =A58+1 -> 46 | B59: Plasma I | C59: Bahan Plasma I | D59: SIKAT GIGI | E59: 0.6252 | F59: BH | G59: 12000 | H59: =+E59*G59 -> 7502.4 | I59: =A59 -> 46 | J59: =D60 -> SHAMPO KECIL | K59: =+B59 -> Plasma I | L59: =SUMIFS($E$14:$E$166,$D$14:$D$166,J59,$B$14:$B$166,K59) -> 0.3126 | M59: =F60 -> BTL | N59: =O59/L59 -> 32000 | O59: =SUMIFS($H$14:$H$166,$D$14:$D$166,J59,$B$14:$B$166,K59) -> 10003.2 | P59: =H59-O59 -> -2500.8 | Q59: Material
A60: =A59+1 -> 47 | B60: Plasma I | C60: Bahan Plasma I | D60: SHAMPO KECIL | E60: 0.3126 | F60: BTL | G60: 32000 | H60: =+E60*G60 -> 10003.2 | I60: =A60 -> 47 | J60: =D61 -> SABUN MANDI | K60: =+B60 -> Plasma I | L60: =SUMIFS($E$14:$E$166,$D$14:$D$166,J60,$B$14:$B$166,K60) -> 0.3126 | M60: =F61 -> BKS | N60: =O60/L60 -> 16000 | O60: =SUMIFS($H$14:$H$166,$D$14:$D$166,J60,$B$14:$B$166,K60) -> 5001.6 | P60: =H60-O60 -> 5001.6 | Q60: Material
A61: =A60+1 -> 48 | B61: Plasma I | C61: Bahan Plasma I | D61: SABUN MANDI | E61: 0.3126 | F61: BKS | G61: 16000 | H61: =+E61*G61 -> 5001.6 | I61: =A61 -> 48 | J61: =D62 -> SAPU LIDI | K61: =+B61 -> Plasma I | L61: =SUMIFS($E$14:$E$166,$D$14:$D$166,J61,$B$14:$B$166,K61) -> 0.2605 | M61: =F62 -> BH | N61: =O61/L61 -> 20000 | O61: =SUMIFS($H$14:$H$166,$D$14:$D$166,J61,$B$14:$B$166,K61) -> 5210 | P61: =H61-O61 -> -208.4 | Q61: Material
A62: =A61+1 -> 49 | B62: Plasma I | C62: Bahan Plasma I | D62: SAPU LIDI | E62: 0.2605 | F62: BH | G62: 20000 | H62: =+E62*G62 -> 5210 | I62: =A62 -> 49 | J62: =D64 -> BAYCLIN 1 LTR | K62: =+B62 -> Plasma I | L62: =SUMIFS($E$14:$E$166,$D$14:$D$166,J62,$B$14:$B$166,K62) -> 0.1042 | M62: =F64 -> BTL | N62: =O62/L62 -> 27000 | O62: =SUMIFS($H$14:$H$166,$D$14:$D$166,J62,$B$14:$B$166,K62) -> 2813.4 | P62: =H62-O62 -> 2396.6 | Q62: Material
A63: =A62+1 -> 50 | B63: Plasma I | C63: Bahan Plasma I | D63: SOKLIN LANTAI | E63: 0.1042 | F63: BKS | G63: 16000 | H63: =+E63*G63 -> 1667.2 | I63: =A63 -> 50 | J63: =D65 -> JAM DINDING MIRADO | K63: =+B63 -> Plasma I | L63: =SUMIFS($E$14:$E$166,$D$14:$D$166,J63,$B$14:$B$166,K63) -> 0.0521 | M63: =+F63 -> BKS | N63: =O63/L63 -> 225000 | O63: =SUMIFS($H$14:$H$166,$D$14:$D$166,J63,$B$14:$B$166,K63) -> 11722.5 | P63: =H63-O63 -> -10055.3 | Q63: Material
A64: =A63+1 -> 51 | B64: Plasma I | C64: Bahan Plasma I | D64: BAYCLIN 1 LTR | E64: 0.1042 | F64: BTL | G64: 27000 | H64: =+E64*G64 -> 2813.4 | I64: =A64 -> 51 | J64: =D66 -> BANTALAN STEMPEL | K64: =+B64 -> Plasma I | L64: =SUMIFS($E$14:$E$166,$D$14:$D$166,J64,$B$14:$B$166,K64) -> 0.0521 | M64: =+F64 -> BTL | N64: =O64/L64 -> 12000 | O64: =SUMIFS($H$14:$H$166,$D$14:$D$166,J64,$B$14:$B$166,K64) -> 625.2 | P64: =H64-O64 -> 2188.2 | Q64: Material
A65: =A64+1 -> 52 | B65: Plasma I | C65: Bahan Plasma I | D65: JAM DINDING MIRADO | E65: 0.0521 | F65: BH | G65: 225000 | H65: =+E65*G65 -> 11722.5 | I65: =A65 -> 52 | J65: =D67 -> ALAT PRASMANAN | K65: =+B65 -> Plasma I | L65: =SUMIFS($E$14:$E$166,$D$14:$D$166,J65,$B$14:$B$166,K65) -> 0.2605 | M65: =+F65 -> BH | N65: =O65/L65 -> 100000 | O65: =SUMIFS($H$14:$H$166,$D$14:$D$166,J65,$B$14:$B$166,K65) -> 26050 | P65: =H65-O65 -> -14327.5 | Q65: Material
A66: =A65+1 -> 53 | B66: Plasma I | C66: Bahan Plasma I | D66: BANTALAN STEMPEL | E66: 0.0521 | F66: BH | G66: 12000 | H66: =+E66*G66 -> 625.2 | I66: =A66 -> 53 | J66: =D69 -> DAIA | K66: =+B66 -> Plasma I | L66: =SUMIFS($E$14:$E$166,$D$14:$D$166,J66,$B$14:$B$166,K66) -> 0.1042 | M66: =F69 -> PCS | N66: =O66/L66 -> 22000 | O66: =SUMIFS($H$14:$H$166,$D$14:$D$166,J66,$B$14:$B$166,K66) -> 2292.4 | P66: =H66-O66 -> -1667.2 | Q66: Material
A67: =A66+1 -> 54 | B67: Plasma I | C67: Bahan Plasma I | D67: ALAT PRASMANAN | E67: 0.2605 | F67: BH | G67: 100000 | H67: =+E67*G67 -> 26050 | I67: =A67 -> 54 | J67: =D70 -> PLEDGE 1LTR | K67: =+B67 -> Plasma I | L67: =SUMIFS($E$14:$E$166,$D$14:$D$166,J67,$B$14:$B$166,K67) -> 0.1563 | M67: =F70 -> PCS | N67: =O67/L67 -> 45000 | O67: =SUMIFS($H$14:$H$166,$D$14:$D$166,J67,$B$14:$B$166,K67) -> 7033.5 | P67: =H67-O67 -> 19016.5 | Q67: Material
...

Sheet Surat_1
B6: INVOICE
B7: Nomor | C7: : | D7: 1a/DMA-PLASMA/I/2025
B8: Tanggal | C8: : | D8: 45688
B9: Jatuh Tempo | C9: : | D9: =D8+30 -> 45718
B10: Lampiran | C10: : | D10: 1 (Satu) Berkas
B12: Kepada Yth.
B13: Koperasi Produsen Pelangi Tanggul Harapan
B14: =VLOOKUP($B$13,Daftar!$C$3:$I$35,2,0) -> Tanggul Harapan No.9 Rt.002 Rw.001, Pematang Limau, Kab.Seruyan
B16: NPWP | C16: : | D16: =VLOOKUP($B$13,Daftar!$C$3:$I$35,3,0) -> 63.797.965.9-712.000
B17: NIK | C17: : | D17: =VLOOKUP($B$13,Daftar!$C$3:$I$35,4,0) -> -
B19: Dengan Hormat,
B20: Bersama ini kami sampaikan biaya pengelolaan kebun kelapa sawit dengan rincian sebagai berikut:
B22: No. | C22: Deskripsi | E22: Jumlah | F22: Satuan | G22: Harga Satuan | H22: Total
B23: 1 | C23: Biaya Pengelolaan Kebun Kelapa Sawit
C24: a. | D24: Upah | H24: =ROUND(SUMIFS('Plasma I 01'!$H$14:$H$112,'Plasma I 01'!$Q$14:$Q$112,Surat_1!D24),0) -> 87634124
C25: b. | D25: Material | H25: =ROUND(SUMIFS('Plasma I 01'!$H$14:$H$112,'Plasma I 01'!$Q$14:$Q$112,Surat_1!D25),0) -> 48048326
C26: c. | D26: Sewa/Rental | H26: =ROUND(SUMIFS('Plasma I 01'!$H$14:$H$112,'Plasma I 01'!$Q$14:$Q$112,Surat_1!D26),0) -> 23646398
C27: d. | D27: Operasional Lainnya | H27: =ROUND(SUMIFS('Plasma I 01'!$H$14:$H$112,'Plasma I 01'!$Q$14:$Q$112,Surat_1!D27),0) -> 0
D28: Jumlah Talangan Biaya Pengelolaan | H28: =SUM(H24:H27) -> 159328848
D29: Management Fee DMA | E29: 0.05 | H29: =ROUND(E29*H28,0) -> 7966442
D30: Jumlah Tagihan | H30: =H28+H29 -> 167295290
D31: DPP PPN | E31: 11/12 | H31: =ROUND(H30*11/12,0) -> 153354016
D32: Pajak Pertambahan Nilai | E32: 0.12 | H32: =ROUND(H31*12%,0) -> 18402482 | K32: Checking
D33: Total | H33: =H30+H32 -> 185697772 | K33: =ROUND(H28-'Plasma I 01'!L139,0) -> 0
B35: Terbilang :
B36: =[1]!terbilang(H33)&" Rupiah" -> Seratus delapan puluh lima juta enam ratus sembilan puluh tujuh ribu tujuh ratus tujuh puluh dua Rupiah
G39: Harap Di transfer ke Rekening:
B40: Catatan : | G40: Bank Mandiri Tab. Bisnis Jakarta
B41: Bukti Potong PPh 23 harap emailkan ke: | G41: Rekening: 006-00-0704639-8
B42: restu.andrian@dmagroup.co.id | G42: A/N: PT. DWI MITRA ADHIUSAHA
G44: Hormat Kami,
G46: Medi Harsa
G47: Ka.Biro Regional Sampit

Sheet Plasma II 01
C8: TAGIHAN BIAYA KEBUN PLASMA II PERIODE JANUARI 2025 | L8: REKAP
C11: N0 | D11: Lahan | E11: PEMINJAMAN | I11: HARGA | K11: No | L11: NAMA | M11: Lahan | N11: JUMLAH | O11: SAT | P11: HARGA | Q11: TOTAL
E12: PEMBEBANAN | F12: NAMA BAHAN | G12: JUMLAH | H12: SAT | I12: HARGA SAT | J12: JUMLAH
K13: Pemakaian Bahan
A14: Material | C14: 1 | D14: Plasma II | E14: Bahan Plasma II | F14: Supremo | G14: 17.06698 | H14: Ltr | I14: 31847.726 | J14: =+G14*I14 -> 543544.5 | K14: =C14 -> 1 | L14: =F14 -> Supremo | M14: =+D14 -> Plasma II | N14: =SUMIFS($G$14:$G$166,$F$14:$F$166,L14,$D$14:$D$166,M14) -> 17.06698 | O14: =+H14 -> Ltr | P14: =Q14/N14 -> 31847.726 | Q14: =SUMIFS($J$14:$J$166,$F$14:$F$166,L14,$D$14:$D$166,M14) -> 543544.5 | R14: =J14-Q14 -> 0
A15: Material | C15: =C14+1 -> 2 | D15: Plasma II | E15: Bahan Plasma II | F15: Supretox | G15: 3.0275 | H15: Ltr | I15: 28711.795 | J15: =+G15*I15 -> 86924.959 | K15: =C15 -> 2 | L15: =F15 -> Supretox | M15: =+D15 -> Plasma II | N15: =SUMIFS($G$14:$G$166,$F$14:$F$166,L15,$D$14:$D$166,M15) -> 3.0275 | O15: =+H15 -> Ltr | P15: =Q15/N15 -> 28711.795 | Q15: =SUMIFS($J$14:$J$166,$F$14:$F$166,L15,$D$14:$D$166,M15) -> 86924.959 | R15: =J15-Q15 -> 0
A16: Material | C16: =C15+1 -> 3 | D16: Plasma II | E16: Bahan Plasma II | F16: Trendy | G16: 915.4753 | H16: Gr | I16: 85.565857 | J16: =+G16*I16 -> 78333.429 | K16: =C16 -> 3 | L16: =F16 -> Trendy | M16: =+D16 -> Plasma II | N16: =SUMIFS($G$14:$G$166,$F$14:$F$166,L16,$D$14:$D$166,M16) -> 915.4753 | O16: =+H16 -> Gr | P16: =Q16/N16 -> 85.565857 | Q16: =SUMIFS($J$14:$J$166,$F$14:$F$166,L16,$D$14:$D$166,M16) -> 78333.429 | R16: =J16-Q16 -> 0
A17: Material | C17: =C16+1 -> 4 | D17: Plasma II | E17: Bahan Plasma II | F17: Triester | G17: 968.8 | H17: Cc | I17: 124.13864 | J17: =+G17*I17 -> 120265.51 | K17: =C17 -> 4 | L17: =F17 -> Triester | M17: =+D17 -> Plasma II | N17: =SUMIFS($G$14:$G$166,$F$14:$F$166,L17,$D$14:$D$166,M17) -> 968.8 | O17: =+H17 -> Cc | P17: =Q17/N17 -> 124.13864 | Q17: =SUMIFS($J$14:$J$166,$F$14:$F$166,L17,$D$14:$D$166,M17) -> 120265.51 | R17: =J17-Q17 -> 0
A18: Material | C18: =C17+1 -> 5 | D18: Plasma II | E18: Bahan Plasma II | F18: Weed.Solution | G18: 10.700235 | H18: Ltr | I18: 33983.366 | J18: =+G18*I18 -> 363630 | K18: =C18 -> 5 | L18: =F18 -> Weed.Solution | M18: =+D18 -> Plasma II | N18: =SUMIFS($G$14:$G$166,$F$14:$F$166,L18,$D$14:$D$166,M18) -> 10.700235 | O18: =+H18 -> Ltr | P18: =Q18/N18 -> 33983.366 | Q18: =SUMIFS($J$14:$J$166,$F$14:$F$166,L18,$D$14:$D$166,M18) -> 363630 | R18: =J18-Q18 -> 0
A19: Material | C19: =C18+1 -> 6 | D19: Plasma II | E19: Bahan Plasma II | F19: POMPA TRANSFER BBM FLOWMETER DIGITAL SOLAR AC 220V | G19: 0.0591 | H19: UNIT | I19: 6960000 | J19: =+G19*I19 -> 411336 | K19: =C19 -> 6 | L19: =F19 -> POMPA TRANSFER BBM FLOWMETER DIGITAL SOLAR AC 220V | M19: =+D19 -> Plasma II | N19: =SUMIFS($G$14:$G$166,$F$14:$F$166,L19,$D$14:$D$166,M19) -> 0.0591 | O19: =+H19 -> UNIT | P19: =Q19/N19 -> 6960000 | Q19: =SUMIFS($J$14:$J$166,$F$14:$F$166,L19,$D$14:$D$166,M19) -> 411336 | R19: =J19-Q19 -> 0
A20: Material | C20: =C19+1 -> 7 | D20: Plasma II | E20: Bahan Plasma II | F20: KIPAS ANGIN BERDIRI | G20: 0.1773 | H20: UNIT | I20: 350000 | J20: =+G20*I20 -> 62055 | K20: =C20 -> 7 | L20: =F20 -> KIPAS ANGIN BERDIRI | M20: =+D20 -> Plasma II | N20: =SUMIFS($G$14:$G$166,$F$14:$F$166,L20,$D$14:$D$166,M20) -> 0.1773 | O20: =+H20 -> UNIT | P20: =Q20/N20 -> 350000 | Q20: =SUMIFS($J$14:$J$166,$F$14:$F$166,L20,$D$14:$D$166,M20) -> 62055 | R20: =J20-Q20 -> 0
A21: Material | C21: =C20+1 -> 8 | D21: Plasma II | E21: Bahan Plasma II | F21: TV LED 24" SHARF | G21: 0.0591 | H21: UNIT | I21: 1650000 | J21: =+G21*I21 -> 97515 | K21: =C21 -> 8 | L21: =F21 -> TV LED 24" SHARF | M21: =+D21 -> Plasma II | N21: =SUMIFS($G$14:$G$166,$F$14:$F$166,L21,$D$14:$D$166,M21) -> 0.0591 | O21: =+H21 -> UNIT | P21: =Q21/N21 -> 1650000 | Q21: =SUMIFS($J$14:$J$166,$F$14:$F$166,L21,$D$14:$D$166,M21) -> 97515 | R21: =J21-Q21 -> 0
A22: Material | C22: =C21+1 -> 9 | D22: Plasma II | E22: Bahan Plasma II | F22: K. VISION SET PAYUNG | G22: 0.0591 | H22: UNIT | I22: 850000 | J22: =G22*I22 -> 50235 | K22: =C22 -> 9 | L22: =F22 -> K. VISION SET PAYUNG | M22: =+D22 -> Plasma II | N22: =SUMIFS($G$14:$G$166,$F$14:$F$166,L22,$D$14:$D$166,M22) -> 0.0591 | O22: =+H22 -> UNIT | P22: =Q22/N22 -> 850000 | Q22: =SUMIFS($J$14:$J$166,$F$14:$F$166,L22,$D$14:$D$166,M22) -> 50235 | R22: =J22-Q22 -> 0
A23: Material | C23: =C22+1 -> 10 | D23: Plasma II | E23: Bahan Plasma II | F23: CHECKING KRANI PANEN | G23: 0.1182 | H23: RIM | I23: 160000 | J23: =G23*I23 -> 18912 | K23: =C23 -> 10 | L23: =F23 -> CHECKING KRANI PANEN | M23: =+D23 -> Plasma II | N23: =SUMIFS($G$14:$G$166,$F$14:$F$166,L23,$D$14:$D$166,M23) -> 0.1182 | O23: =+H23 -> RIM | P23: =Q23/N23 -> 160000 | Q23: =SUMIFS($J$14:$J$166,$F$14:$F$166,L23,$D$14:$D$166,M23) -> 18912 | R23: =J23-Q23 -> 0
A24: Material | C24: =C23+1 -> 11 | D24: Plasma II | E24: Bahan Plasma II | F24: PENGANTAR TBS | G24: 0.1773 | H24: RIM | I24: 160000 | J24: =G24*I24 -> 28368 | K24: =C24 -> 11 | L24: =F24 -> PENGANTAR TBS | M24: =+D24 -> Plasma II | N24: =SUMIFS($G$14:$G$166,$F$14:$F$166,L24,$D$14:$D$166,M24) -> 0.1773 | O24: =+H24 -> RIM | P24: =Q24/N24 -> 160000 | Q24: =SUMIFS($J$14:$J$166,$F$14:$F$166,L24,$D$14:$D$166,M24) -> 28368 | R24: =J24-Q24 -> 0
A25: Material | C25: =C24+1 -> 12 | D25: Plasma II | E25: Bahan Plasma II | F25: DATA KWALITAS TBS | G25: 0.2955 | H25: RIM | I25: 160000 | J25: =G25*I25 -> 47280 | K25: =C25 -> 12 | L25: =F25 -> DATA KWALITAS TBS | M25: =+D25 -> Plasma II | N25: =SUMIFS($G$14:$G$166,$F$14:$F$166,L25,$D$14:$D$166,M25) -> 0.2955 | O25: =+H25 -> RIM | P25: =Q25/N25 -> 160000 | Q25: =SUMIFS($J$14:$J$166,$F$14:$F$166,L25,$D$14:$D$166,M25) -> 47280 | R25: =J25-Q25 -> 0
A26: Material | C26: =C25+1 -> 13 | D26: Plasma II | E26: Bahan Plasma II | F26: PERAWATAN | G26: 0.2955 | H26: RIM | I26: 160000 | J26: =G26*I26 -> 47280 | K26: =C26 -> 13 | L26: =F26 -> PERAWATAN | M26: =+D26 -> Plasma II | N26: =SUMIFS($G$14:$G$166,$F$14:$F$166,L26,$D$14:$D$166,M26) -> 0.2955 | O26: =+H26 -> RIM | P26: =Q26/N26 -> 160000 | Q26: =SUMIFS($J$14:$J$166,$F$14:$F$166,L26,$D$14:$D$166,M26) -> 47280 | R26: =J26-Q26 -> 0
A27: Material | C27: =C26+1 -> 14 | D27: Plasma II | E27: Bahan Plasma II | F27: ANCAK PANEN | G27: 0.591 | H27: RIM | I27: 160000 | J27: =G27*I27 -> 94560 | K27: =C27 -> 14 | L27: =F27 -> ANCAK PANEN | M27: =+D27 -> Plasma II | N27: =SUMIFS($G$14:$G$166,$F$14:$F$166,L27,$D$14:$D$166,M27) -> 0.591 | O27: =+H27 -> RIM | P27: =Q27/N27 -> 160000 | Q27: =SUMIFS($J$14:$J$166,$F$14:$F$166,L27,$D$14:$D$166,M27) -> 94560 | R27: =J27-Q27 -> 0
A28: Material | C28: =C27+1 -> 15 | D28: Plasma II | E28: Bahan Plasma II | F28: PENGEMBALIAN BARANG BEKAS | G28: 0.0591 | H28: RIM | I28: 160000 | J28: =G28*I28 -> 9456 | K28: =C28 -> 15 | L28: =F28 -> PENGEMBALIAN BARANG BEKAS | M28: =+D28 -> Plasma II | N28: =SUMIFS($G$14:$G$166,$F$14:$F$166,L28,$D$14:$D$166,M28) -> 0.0591 | O28: =+H28 -> RIM | P28: =Q28/N28 -> 160000 | Q28: =SUMIFS($J$14:$J$166,$F$14:$F$166,L28,$D$14:$D$166,M28) -> 9456 | R28: =J28-Q28 -> 0
A29: Material | C29: =C28+1 -> 16 | D29: Plasma II | E29: Bahan Plasma II | F29: SPB | G29: 0.0591 | H29: RIM | I29: 160000 | J29: =G29*I29 -> 9456 | K29: =C29 -> 16 | L29: =F29 -> SPB | M29: =+D29 -> Plasma II | N29: =SUMIFS($G$14:$G$166,$F$14:$F$166,L29,$D$14:$D$166,M29) -> 0.0591 | O29: =+H29 -> RIM | P29: =Q29/N29 -> 160000 | Q29: =SUMIFS($J$14:$J$166,$F$14:$F$166,L29,$D$14:$D$166,M29) -> 9456 | R29: =J29-Q29 -> 0
A30: Material | C30: =C29+1 -> 17 | D30: Plasma II | E30: Bahan Plasma II | F30: PASS KELUAR | G30: 0.0591 | H30: RIM | I30: 160000 | J30: =G30*I30 -> 9456 | K30: =C30 -> 17 | L30: =F30 -> PASS KELUAR | M30: =+D30 -> Plasma II | N30: =SUMIFS($G$14:$G$166,$F$14:$F$166,L30,$D$14:$D$166,M30) -> 0.0591 | O30: =+H30 -> RIM | P30: =Q30/N30 -> 160000 | Q30: =SUMIFS($J$14:$J$166,$F$14:$F$166,L30,$D$14:$D$166,M30) -> 9456 | R30: =J30-Q30 -> 0
A31: Material | C31: =C30+1 -> 18 | D31: Plasma II | E31: Bahan Plasma II | F31: LAP. PROGRAM LERJA DIVISI | G31: 0.0591 | H31: RIM | I31: 160000 | J31: =G31*I31 -> 9456 | K31: =C31 -> 18 | L31: =F31 -> LAP. PROGRAM LERJA DIVISI | M31: =+D31 -> Plasma II | N31: =SUMIFS($G$14:$G$166,$F$14:$F$166,L31,$D$14:$D$166,M31) -> 0.0591 | O31: =+H31 -> RIM | P31: =Q31/N31 -> 160000 | Q31: =SUMIFS($J$14:$J$166,$F$14:$F$166,L31,$D$14:$D$166,M31) -> 9456 | R31: =J31-Q31 -> 0
A32: Material | C32: =C31+1 -> 19 | D32: Plasma II | E32: Bahan Plasma II | F32: BPBG | G32: 0.0591 | H32: RIM | I32: 160000 | J32: =G32*I32 -> 9456 | K32: =C32 -> 19 | L32: =F32 -> BPBG | M32: =+D32 -> Plasma II | N32: =SUMIFS($G$14:$G$166,$F$14:$F$166,L32,$D$14:$D$166,M32) -> 0.0591 | O32: =+H32 -> RIM | P32: =Q32/N32 -> 160000 | Q32: =SUMIFS($J$14:$J$166,$F$14:$F$166,L32,$D$14:$D$166,M32) -> 9456 | R32: =J32-Q32 -> 0
A33: Material | C33: =C32+1 -> 20 | D33: Plasma II | E33: Bahan Plasma II | F33: PEN KENKO | G33: 0.8865 | H33: PCS | I33: 5000 | J33: =G33*I33 -> 4432.5 | K33: =C33 -> 20 | L33: =F33 -> PEN KENKO | M33: =+D33 -> Plasma II | N33: =SUMIFS($G$14:$G$166,$F$14:$F$166,L33,$D$14:$D$166,M33) -> 1.182 | O33: =+H33 -> PCS | P33: =Q33/N33 -> 5000 | Q33: =SUMIFS($J$14:$J$166,$F$14:$F$166,L33,$D$14:$D$166,M33) -> 5910 | R33: =J33-Q33 -> -1477.5
... A50: Material | C50: =C49+1 -> 37 | D50: Plasma II | E50: Bahan Plasma II | F50: GUNTING | G50: 0.0591 | H50: PCS | I50: 17000 | J50: =G50*I50 -> 1004.7 | K50: =C50 -> 37 | L50: =F50 -> GUNTING | M50: =+D50 -> Plasma II | N50: =SUMIFS($G$14:$G$166,$F$14:$F$166,L50,$D$14:$D$166,M50) -> 0.0591 | O50: =+H50 -> PCS | P50: =Q50/N50 -> 17000 | Q50: =SUMIFS($J$14:$J$166,$F$14:$F$166,L50,$D$14:$D$166,M50) -> 1004.7 | R50: =J50-Q50 -> 0
A51: Material | C51: =C50+1 -> 38 | D51: Plasma II | E51: Bahan Plasma II | F51: PEN KENKO | G51: 0.2955 | H51: PCS | I51: 5000 | J51: =G51*I51 -> 1477.5 | K51: =C51 -> 38 | L51: =F52 -> POST IT | M51: =+D51 -> Plasma II | N51: =SUMIFS($G$14:$G$166,$F$14:$F$166,L51,$D$14:$D$166,M51) -> 0.1182 | O51: =H52 -> PCS | P51: =Q51/N51 -> 24000 | Q51: =SUMIFS($J$14:$J$166,$F$14:$F$166,L51,$D$14:$D$166,M51) -> 2836.8 | R51: =J52-Q51 -> 0
A52: Material | C52: =C51+1 -> 39 | D52: Plasma II | E52: Bahan Plasma II | F52: POST IT | G52: 0.1182 | H52: PCS | I52: 24000 | J52: =G52*I52 -> 2836.8 | K52: =C52 -> 39 | L52: =F53 -> STELLA MATIC REFILL | M52: =+D52 -> Plasma II | N52: =SUMIFS($G$14:$G$166,$F$14:$F$166,L52,$D$14:$D$166,M52) -> 0.1773 | O52: =H53 -> PCS | P52: =Q52/N52 -> 37000 | Q52: =SUMIFS($J$14:$J$166,$F$14:$F$166,L52,$D$14:$D$166,M52) -> 6560.1 | R52: =J53-Q52 -> 0
A53: Material | C53: =C52+1 -> 40 | D53: Plasma II | E53: Bahan Plasma II | F53: STELLA MATIC REFILL | G53: 0.1773 | H53: PCS | I53: 37000 | J53: =G53*I53 -> 6560.1 | K53: =C53 -> 40 | L53: =F54 -> TISSU 900GR | M53: =+D53 -> Plasma II | N53: =SUMIFS($G$14:$G$166,$F$14:$F$166,L53,$D$14:$D$166,M53) -> 0.0591 | O53: =H54 -> PCS | P53: =Q53/N53 -> 50000 | Q53: =SUMIFS($J$14:$J$166,$F$14:$F$166,L53,$D$14:$D$166,M53) -> 2955 | R53: =J54-Q53 -> 0
A54: Material | C54: =C53+1 -> 41 | D54: Plasma II | E54: Bahan Plasma II | F54: TISSU 900GR | G54: 0.0591 | H54: PCS | I54: 50000 | J54: =G54*I54 -> 2955 | K54: =C54 -> 41 | L54: =F55 -> SOKLIN LANTAI | M54: =+D54 -> Plasma II | N54: =SUMIFS($G$14:$G$166,$F$14:$F$166,L54,$D$14:$D$166,M54) -> 0.4728 | O54: =H55 -> PCS | P54: =Q54/N54 -> 16000 | Q54: =SUMIFS($J$14:$J$166,$F$14:$F$166,L54,$D$14:$D$166,M54) -> 7564.8 | R54: =J55-Q54 -> -4728
A55: Material | C55: =C54+1 -> 42 | D55: Plasma II | E55: Bahan Plasma II | F55: SOKLIN LANTAI | G55: 0.1773 | H55: PCS | I55: 16000 | J55: =G55*I55 -> 2836.8 | K55: =C55 -> 42 | L55: =F56 -> MESIN POMPA AIR PANASONIC GP 200 JXK NON OTOMATIS | M55: =+D55 -> Plasma II | N55: =SUMIFS($G$14:$G$166,$F$14:$F$166,L55,$D$14:$D$166,M55) -> 0.0591 | O55: =H56 -> UNIT | P55: =Q55/N55 -> 854800 | Q55: =SUMIFS($J$14:$J$166,$F$14:$F$166,L55,$D$14:$D$166,M55) -> 50518.68 | R55: =J56-Q55 -> 0
A56: Material | C56: =C55+1 -> 43 | D56: Plasma II | E56: Bahan Plasma II | F56: MESIN POMPA AIR PANASONIC GP 200 JXK NON OTOMATIS | G56: 0.0591 | H56: UNIT | I56: 854800 | J56: =G56*I56 -> 50518.68 | K56: =C56 -> 43 | L56: =F57 -> RAPIKA | M56: =+D56 -> Plasma II | N56: =SUMIFS($G$14:$G$166,$F$14:$F$166,L56,$D$14:$D$166,M56) -> 0.1182 | O56: =H57 -> BTL | P56: =Q56/N56 -> 11000 | Q56: =SUMIFS($J$14:$J$166,$F$14:$F$166,L56,$D$14:$D$166,M56) -> 1300.2 | R56: =J57-Q56 -> 0
A57: Material | C57: =C56+1 -> 44 | D57: Plasma II | E57: Bahan Plasma II | F57: RAPIKA | G57: 0.1182 | H57: BTL | I57: 11000 | J57: =G57*I57 -> 1300.2 | K57: =C57 -> 44 | L57: =F58 -> SIKAT GIGI | M57: =+D57 -> Plasma II | N57: =SUMIFS($G$14:$G$166,$F$14:$F$166,L57,$D$14:$D$166,M57) -> 0.7092 | O57: =H58 -> BH | P57: =Q57/N57 -> 12000 | Q57: =SUMIFS($J$14:$J$166,$F$14:$F$166,L57,$D$14:$D$166,M57) -> 8510.4 | R57: =J58-Q57 -> 0
A58: Material | C58: =C57+1 -> 45 | D58: Plasma II | E58: Bahan Plasma II | F58: SIKAT GIGI | G58: 0.7092 | H58: BH | I58: 12000 | J58: =G58*I58 -> 8510.4 | K58: =C58 -> 45 | L58: =F59 -> SHAMPO KECIL | M58: =+D58 -> Plasma II | N58: =SUMIFS($G$14:$G$166,$F$14:$F$166,L58,$D$14:$D$166,M58) -> 0.3546 | O58: =H59 -> BTL | P58: =Q58/N58 -> 32000 | Q58: =SUMIFS($J$14:$J$166,$F$14:$F$166,L58,$D$14:$D$166,M58) -> 11347.2 | R58: =J59-Q58 -> 0
A59: Material | C59: =C58+1 -> 46 | D59: Plasma II | E59: Bahan Plasma II | F59: SHAMPO KECIL | G59: 0.3546 | H59: BTL | I59: 32000 | J59: =G59*I59 -> 11347.2 | K59: =C59 -> 46 | L59: =F60 -> SABUN MANDI | M59: =+D59 -> Plasma II | N59: =SUMIFS($G$14:$G$166,$F$14:$F$166,L59,$D$14:$D$166,M59) -> 0.3546 | O59: =H60 -> BKS | P59: =Q59/N59 -> 16000 | Q59: =SUMIFS($J$14:$J$166,$F$14:$F$166,L59,$D$14:$D$166,M59) -> 5673.6 | R59: =J60-Q59 -> 0
A60: Material | C60: =C59+1 -> 47 | D60: Plasma II | E60: Bahan Plasma II | F60: SABUN MANDI | G60: 0.3546 | H60: BKS | I60: 16000 | J60: =G60*I60 -> 5673.6 | K60: =C60 -> 47 | L60: =F61 -> SAPU LIDI | M60: =+D60 -> Plasma II | N60: =SUMIFS($G$14:$G$166,$F$14:$F$166,L60,$D$14:$D$166,M60) -> 0.2955 | O60: =H61 -> BH | P60: =Q60/N60 -> 20000 | Q60: =SUMIFS($J$14:$J$166,$F$14:$F$166,L60,$D$14:$D$166,M60) -> 5910 | R60: =J61-Q60 -> 0
A61: Material | C61: =C60+1 -> 48 | D61: Plasma II | E61: Bahan Plasma II | F61: SAPU LIDI | G61: 0.2955 | H61: BH | I61: 20000 | J61: =G61*I61 -> 5910 | K61: =C61 -> 48 | L61: =F63 -> BAYCLIN 1 LTR | M61: =+D61 -> Plasma II | N61: =SUMIFS($G$14:$G$166,$F$14:$F$166,L61,$D$14:$D$166,M61) -> 0.1182 | O61: =H63 -> BTL | P61: =Q61/N61 -> 27000 | Q61: =SUMIFS($J$14:$J$166,$F$14:$F$166,L61,$D$14:$D$166,M61) -> 3191.4 | R61: =J63-Q61 -> 0
A62: Material | C62: =C61+1 -> 49 | D62: Plasma II | E62: Bahan Plasma II | F62: SOKLIN LANTAI | G62: 0.1182 | H62: BKS | I62: 16000 | J62: =G62*I62 -> 1891.2 | K62: =C62 -> 49 | L62: =F64 -> JAM DINDING MIRADO | M62: =+D62 -> Plasma II | N62: =SUMIFS($G$14:$G$166,$F$14:$F$166,L62,$D$14:$D$166,M62) -> 0.0591 | O62: =H64 -> BH | P62: =Q62/N62 -> 225000 | Q62: =SUMIFS($J$14:$J$166,$F$14:$F$166,L62,$D$14:$D$166,M62) -> 13297.5 | R62: =J64-Q62 -> 0
A63: Material | C63: =C62+1 -> 50 | D63: Plasma II | E63: Bahan Plasma II | F63: BAYCLIN 1 LTR | G63: 0.1182 | H63: BTL | I63: 27000 | J63: =G63*I63 -> 3191.4 | K63: =C63 -> 50 | L63: =F65 -> BANTALAN STEMPEL | M63: =+D63 -> Plasma II | N63: =SUMIFS($G$14:$G$166,$F$14:$F$166,L63,$D$14:$D$166,M63) -> 0.0591 | O63: =H65 -> BH | P63: =Q63/N63 -> 12000 | Q63: =SUMIFS($J$14:$J$166,$F$14:$F$166,L63,$D$14:$D$166,M63) -> 709.2 | R63: =J65-Q63 -> 0
A64: Material | C64: =C63+1 -> 51 | D64: Plasma II | E64: Bahan Plasma II | F64: JAM DINDING MIRADO | G64: 0.0591 | H64: BH | I64: 225000 | J64: =G64*I64 -> 13297.5 | K64: =C64 -> 51 | L64: =F66 -> ALAT PRASMANAN | M64: =+D64 -> Plasma II | N64: =SUMIFS($G$14:$G$166,$F$14:$F$166,L64,$D$14:$D$166,M64) -> 0.2955 | O64: =H66 -> BH | P64: =Q64/N64 -> 100000 | Q64: =SUMIFS($J$14:$J$166,$F$14:$F$166,L64,$D$14:$D$166,M64) -> 29550 | R64: =J66-Q64 -> 0
A65: Material | C65: =C64+1 -> 52 | D65: Plasma II | E65: Bahan Plasma II | F65: BANTALAN STEMPEL | G65: 0.0591 | H65: BH | I65: 12000 | J65: =G65*I65 -> 709.2 | K65: =C65 -> 52 | L65: =F68 -> DAIA | M65: =+D65 -> Plasma II | N65: =SUMIFS($G$14:$G$166,$F$14:$F$166,L65,$D$14:$D$166,M65) -> 0.1182 | O65: =H67 -> PCS | P65: =Q65/N65 -> 22000 | Q65: =SUMIFS($J$14:$J$166,$F$14:$F$166,L65,$D$14:$D$166,M65) -> 2600.4 | R65: =J67-Q65 -> 236.4
...

Sheet Surat_2
B6: INVOICE
B7: Nomor | C7: : | D7: 1b/DMA-PLASMA/I/2025
B8: Tanggal | C8: : | D8: 45688
B9: Jatuh Tempo | C9: : | D9: =D8+30 -> 45718
B10: Lampiran | C10: : | D10: 1 (Satu) Berkas
B12: Kepada Yth.
B13: Koperasi Produsen Berkah Natai Mandiri
B14: =VLOOKUP($B$13,Daftar!$C$3:$I$35,2,0) -> Jl.Desa Natai Baru Rt.001 Rw.001, Natai Baru, Kab.Kotawaringin Timur
B16: NPWP | C16: : | D16: =VLOOKUP($B$13,Daftar!$C$3:$I$35,3,0) -> 63.087.816.3-712.000
B17: NIK | C17: : | D17: =VLOOKUP($B$13,Daftar!$C$3:$I$35,4,0) -> -
B19: Dengan Hormat,
B20: Bersama ini kami sampaikan biaya pengelolaan kebun kelapa sawit dengan rincian sebagai berikut:
B22: No. | C22: Deskripsi | E22: Jumlah | F22: Satuan | G22: Harga Satuan | H22: Total
B23: 1 | C23: Biaya Pengelolaan Kebun Kelapa Sawit
C24: a. | D24: Upah | H24: =ROUND(SUMIFS('Plasma II 01'!$J$14:$J$97,'Plasma II 01'!$A$14:$A$97,Surat_2!D24),0) -> 108068654
C25: b. | D25: Material | H25: =ROUND(SUMIFS('Plasma II 01'!$J$14:$J$97,'Plasma II 01'!$A$14:$A$97,Surat_2!D25),0) -> 33417655
C26: c. | D26: Sewa/Rental | H26: =ROUND(SUMIFS('Plasma II 01'!$J$14:$J$97,'Plasma II 01'!$A$14:$A$97,Surat_2!D26),0) -> 27393219
C27: d. | D27: Operasional Lainnya | H27: =ROUND(SUMIFS('Plasma II 01'!$J$14:$J$97,'Plasma II 01'!$A$14:$A$97,Surat_2!D27),0) -> 639662
D28: Jumlah Talangan Biaya Pengelolaan | H28: =SUM(H24:H27) -> 169519190
D29: Management Fee DMA | E29: 0.05 | H29: =ROUND(E29*H28,0) -> 8475960
D30: Jumlah Tagihan | H30: =H28+H29 -> 177995150
D31: DPP PPN | E31: 11/12 | H31: =ROUND(H30*11/12,0) -> 163162221
D32: Pajak Pertambahan Nilai | E32: 0.12 | H32: =ROUND(H31*12%,0) -> 19579467 | K32: Checking
D33: Total | H33: =H30+H32 -> 197574617 | K33: =ROUND(H28-'Plasma II 01'!N111,0) -> 0
B35: Terbilang :
B36: Seratus sembilan puluh tujuh juta empat ratus lima ribu sembilan puluh delapan Rupiah
G39: Harap Di transfer ke Rekening:
B40: Catatan : | G40: Bank Mandiri Tab. Bisnis Jakarta
B41: Bukti Potong PPh 23 harap emailkan ke: | G41: Rekening: 006-00-0704639-8
B42: restu.andrian@dmagroup.co.id | G42: A/N: PT. DWI MITRA ADHIUSAHA
G44: Hormat Kami,
G46: Medi Harsa
G47: Ka.Biro Regional Sampit

Sheet Surat
B7: No | C7: : 01/GM/Kbn-PT.DMA/ II /2025
B8: Lampiran | C8: : Terlampir
B9: Perihal | C9: : Tagihan Pemakaian Bahan
B12: Kepada Yth,
B13: Ketua Koperasi Produsen Pelangi Tanggul Harapan
B14: Ka Biro Regional Sampit
B15: Di-
C16: Tempat
B19: Dengan Hormat
B20: Bersama Ini kami sampaikan pemakaian bahan Koperasi Produsen Pelangi Tanggul Harapan
B21: Periode Januari 2025, adalah sebagai berikut:
B23: No | C23: Kebun | D23: Total | F23: Keterangan
B25: 1 | C25: Kop Produsen Pelangi Tanggul Harapan | D25: =Surat_1!H33 -> 185697772
B27: Total | D27: =+SUM(D25:D26) -> 185697772
B29: Adapun perincian pemakaian bahan terlampir.
B31: Demikian kami sampaikan, atas perhatian dan kerja samanya kami ucapkan terimakasih
E33: Kebun PT DMA, 13 Februari 2025
E34: Hormat Kami
E38: Salamuddin Nahar
E39: General Manager Regional Sampit
B41: Tembusan:
B42: 1. | C42: Direktur Utama Regional Sampit
B43: 2 | C43: Direktur Operasional Regional Sampit
B44: 3 | C44: File
B51: No | C51: : 01/GM/Kbn-PT.DMA/ II /2025
B52: Lampiran | C52: : Terlampir
B53: Perihal | C53: : Tagihan Pemakaian Bahan
B56: Kepada Yth,
B57: Ketua Koperasi Produsen Natai Berkah Mandiri
B58: Ka Biro Regional Sampit
B59: Di-
C60: Tempat
B63: Dengan Hormat
B64: Bersama Ini kami sampaikan pemakaian bahan Koperasi Produsen Natai Berkah Mandiri
B65: Periode Januari 2025, adalah sebagai berikut:
B67: No | C67: Kebun | D67: Total | F67: Keterangan
B69: 1 | C69: Kop Produsen Natai Berkah Mandiri | D69: =Surat_2!H33 -> 197574617
B71: Total | D71: =+SUM(D69:D70) -> 197574617
B73: Adapun perincian pemakaian bahan terlampir.
B75: Demikian kami sampaikan, atas perhatian dan kerja samanya kami ucapkan terimakasih
...
